2018-08-14 15:26:24,037 INFO: Microblog startup [in /home/nick/AcronisAPP/app/__init__.py:44]
2018-08-14 15:26:34,041 ERROR: Exception on /edit_profile [GET] [in /home/nick/AcronisAPP/Acronis_Backup_API/lib/python3.6/site-packages/flask/app.py:1761]
Traceback (most recent call last):
  File "/home/nick/AcronisAPP/Acronis_Backup_API/lib/python3.6/site-packages/flask/app.py", line 2292, in wsgi_app
    response = self.full_dispatch_request()
  File "/home/nick/AcronisAPP/Acronis_Backup_API/lib/python3.6/site-packages/flask/app.py", line 1815, in full_dispatch_request
    rv = self.handle_user_exception(e)
  File "/home/nick/AcronisAPP/Acronis_Backup_API/lib/python3.6/site-packages/flask/app.py", line 1718, in handle_user_exception
    reraise(exc_type, exc_value, tb)
  File "/home/nick/AcronisAPP/Acronis_Backup_API/lib/python3.6/site-packages/flask/_compat.py", line 35, in reraise
    raise value
  File "/home/nick/AcronisAPP/Acronis_Backup_API/lib/python3.6/site-packages/flask/app.py", line 1813, in full_dispatch_request
    rv = self.dispatch_request()
  File "/home/nick/AcronisAPP/Acronis_Backup_API/lib/python3.6/site-packages/flask/app.py", line 1799, in dispatch_request
    return self.view_functions[rule.endpoint](**req.view_args)
  File "/home/nick/AcronisAPP/Acronis_Backup_API/lib/python3.6/site-packages/flask_login/utils.py", line 261, in decorated_view
    return func(*args, **kwargs)
  File "/home/nick/AcronisAPP/app/routes.py", line 85, in edit_profile
    form = EditProfileForm()
  File "/home/nick/AcronisAPP/Acronis_Backup_API/lib/python3.6/site-packages/wtforms/form.py", line 212, in __call__
    return type.__call__(cls, *args, **kwargs)
TypeError: __init__() missing 1 required positional argument: 'original_username'
2018-08-14 15:26:42,777 ERROR: Exception on /edit_profile [GET] [in /home/nick/AcronisAPP/Acronis_Backup_API/lib/python3.6/site-packages/flask/app.py:1761]
Traceback (most recent call last):
  File "/home/nick/AcronisAPP/Acronis_Backup_API/lib/python3.6/site-packages/flask/app.py", line 2292, in wsgi_app
    response = self.full_dispatch_request()
  File "/home/nick/AcronisAPP/Acronis_Backup_API/lib/python3.6/site-packages/flask/app.py", line 1815, in full_dispatch_request
    rv = self.handle_user_exception(e)
  File "/home/nick/AcronisAPP/Acronis_Backup_API/lib/python3.6/site-packages/flask/app.py", line 1718, in handle_user_exception
    reraise(exc_type, exc_value, tb)
  File "/home/nick/AcronisAPP/Acronis_Backup_API/lib/python3.6/site-packages/flask/_compat.py", line 35, in reraise
    raise value
  File "/home/nick/AcronisAPP/Acronis_Backup_API/lib/python3.6/site-packages/flask/app.py", line 1813, in full_dispatch_request
    rv = self.dispatch_request()
  File "/home/nick/AcronisAPP/Acronis_Backup_API/lib/python3.6/site-packages/flask/app.py", line 1799, in dispatch_request
    return self.view_functions[rule.endpoint](**req.view_args)
  File "/home/nick/AcronisAPP/Acronis_Backup_API/lib/python3.6/site-packages/flask_login/utils.py", line 261, in decorated_view
    return func(*args, **kwargs)
  File "/home/nick/AcronisAPP/app/routes.py", line 85, in edit_profile
    form = EditProfileForm()
  File "/home/nick/AcronisAPP/Acronis_Backup_API/lib/python3.6/site-packages/wtforms/form.py", line 212, in __call__
    return type.__call__(cls, *args, **kwargs)
TypeError: __init__() missing 1 required positional argument: 'original_username'
2018-08-14 15:31:16,181 INFO: Microblog startup [in /home/nick/AcronisAPP/app/__init__.py:44]
2018-08-14 15:31:21,611 ERROR: Exception on /edit_profile [GET] [in /home/nick/AcronisAPP/Acronis_Backup_API/lib/python3.6/site-packages/flask/app.py:1761]
Traceback (most recent call last):
  File "/home/nick/AcronisAPP/Acronis_Backup_API/lib/python3.6/site-packages/flask/app.py", line 2292, in wsgi_app
    response = self.full_dispatch_request()
  File "/home/nick/AcronisAPP/Acronis_Backup_API/lib/python3.6/site-packages/flask/app.py", line 1815, in full_dispatch_request
    rv = self.handle_user_exception(e)
  File "/home/nick/AcronisAPP/Acronis_Backup_API/lib/python3.6/site-packages/flask/app.py", line 1718, in handle_user_exception
    reraise(exc_type, exc_value, tb)
  File "/home/nick/AcronisAPP/Acronis_Backup_API/lib/python3.6/site-packages/flask/_compat.py", line 35, in reraise
    raise value
  File "/home/nick/AcronisAPP/Acronis_Backup_API/lib/python3.6/site-packages/flask/app.py", line 1813, in full_dispatch_request
    rv = self.dispatch_request()
  File "/home/nick/AcronisAPP/Acronis_Backup_API/lib/python3.6/site-packages/flask/app.py", line 1799, in dispatch_request
    return self.view_functions[rule.endpoint](**req.view_args)
  File "/home/nick/AcronisAPP/Acronis_Backup_API/lib/python3.6/site-packages/flask_login/utils.py", line 261, in decorated_view
    return func(*args, **kwargs)
  File "/home/nick/AcronisAPP/app/routes.py", line 85, in edit_profile
    form = EditProfileForm()
  File "/home/nick/AcronisAPP/Acronis_Backup_API/lib/python3.6/site-packages/wtforms/form.py", line 212, in __call__
    return type.__call__(cls, *args, **kwargs)
TypeError: __init__() missing 1 required positional argument: 'original_username'
2018-08-14 15:31:37,339 ERROR: Exception on /edit_profile [GET] [in /home/nick/AcronisAPP/Acronis_Backup_API/lib/python3.6/site-packages/flask/app.py:1761]
Traceback (most recent call last):
  File "/home/nick/AcronisAPP/Acronis_Backup_API/lib/python3.6/site-packages/flask/app.py", line 2292, in wsgi_app
    response = self.full_dispatch_request()
  File "/home/nick/AcronisAPP/Acronis_Backup_API/lib/python3.6/site-packages/flask/app.py", line 1815, in full_dispatch_request
    rv = self.handle_user_exception(e)
  File "/home/nick/AcronisAPP/Acronis_Backup_API/lib/python3.6/site-packages/flask/app.py", line 1718, in handle_user_exception
    reraise(exc_type, exc_value, tb)
  File "/home/nick/AcronisAPP/Acronis_Backup_API/lib/python3.6/site-packages/flask/_compat.py", line 35, in reraise
    raise value
  File "/home/nick/AcronisAPP/Acronis_Backup_API/lib/python3.6/site-packages/flask/app.py", line 1813, in full_dispatch_request
    rv = self.dispatch_request()
  File "/home/nick/AcronisAPP/Acronis_Backup_API/lib/python3.6/site-packages/flask/app.py", line 1799, in dispatch_request
    return self.view_functions[rule.endpoint](**req.view_args)
  File "/home/nick/AcronisAPP/Acronis_Backup_API/lib/python3.6/site-packages/flask_login/utils.py", line 261, in decorated_view
    return func(*args, **kwargs)
  File "/home/nick/AcronisAPP/app/routes.py", line 85, in edit_profile
    form = EditProfileForm()
  File "/home/nick/AcronisAPP/Acronis_Backup_API/lib/python3.6/site-packages/wtforms/form.py", line 212, in __call__
    return type.__call__(cls, *args, **kwargs)
TypeError: __init__() missing 1 required positional argument: 'original_username'
2018-08-14 15:36:23,205 INFO: Microblog startup [in /home/nick/AcronisAPP/app/__init__.py:44]
2018-08-14 15:36:26,084 ERROR: Exception on /edit_profile [GET] [in /home/nick/AcronisAPP/Acronis_Backup_API/lib/python3.6/site-packages/flask/app.py:1761]
Traceback (most recent call last):
  File "/home/nick/AcronisAPP/Acronis_Backup_API/lib/python3.6/site-packages/flask/app.py", line 2292, in wsgi_app
    response = self.full_dispatch_request()
  File "/home/nick/AcronisAPP/Acronis_Backup_API/lib/python3.6/site-packages/flask/app.py", line 1815, in full_dispatch_request
    rv = self.handle_user_exception(e)
  File "/home/nick/AcronisAPP/Acronis_Backup_API/lib/python3.6/site-packages/flask/app.py", line 1718, in handle_user_exception
    reraise(exc_type, exc_value, tb)
  File "/home/nick/AcronisAPP/Acronis_Backup_API/lib/python3.6/site-packages/flask/_compat.py", line 35, in reraise
    raise value
  File "/home/nick/AcronisAPP/Acronis_Backup_API/lib/python3.6/site-packages/flask/app.py", line 1813, in full_dispatch_request
    rv = self.dispatch_request()
  File "/home/nick/AcronisAPP/Acronis_Backup_API/lib/python3.6/site-packages/flask/app.py", line 1799, in dispatch_request
    return self.view_functions[rule.endpoint](**req.view_args)
  File "/home/nick/AcronisAPP/Acronis_Backup_API/lib/python3.6/site-packages/flask_login/utils.py", line 261, in decorated_view
    return func(*args, **kwargs)
  File "/home/nick/AcronisAPP/app/routes.py", line 85, in edit_profile
    form = EditProfileForm()
  File "/home/nick/AcronisAPP/Acronis_Backup_API/lib/python3.6/site-packages/wtforms/form.py", line 212, in __call__
    return type.__call__(cls, *args, **kwargs)
TypeError: __init__() missing 1 required positional argument: 'original_username'
2018-08-14 15:43:19,497 INFO: Microblog startup [in /home/nick/AcronisAPP/app/__init__.py:44]
